Workbook

Sheet Übersicht
A1: Via Romae – Questgruppierung und Implementierung v0.9
A2: 40 Questdefinitionen mit 396 Ablauf-Schritten; EnemyBalance und Stores sind verbindliche Balancing-/Datenverträge für GDD v0.16 und GeoJSON v0.9.
A4: Regulär | B4: Tag 1 | C4: Tag 2 | D4: Medien | E4: Hidden | F4: Bosse | G4: Ein-Ort | H4: Mehrort | I4: Ø Eignung | J4: Rote Pflichtorte | K4: Unique Gegner | L4: Unique Tag 1 | M4: Unique Tag 2 | N4: Questdefs | O4: Ablaufschritte | P4: Dialogknoten | Q4: Charaktere | R4: Rätsel | S4: Kampfprofile | T4: Navigation | U4: Timerquests | V4: Checks OK
A5: =COUNTA(Questgruppen!$B$5:$B$30) -> 26 | B5: =COUNTIF(Questgruppen!$C$5:$C$30,"DAY_1") -> 16 | C5: =COUNTIF(Questgruppen!$C$5:$C$30,"DAY_2") -> 10 | D5: =COUNTIF(Sonderquests!$C$5:$C$18,"MEDIA_LOCAL")+COUNTIF(Sonderquests!$C$5:$C$18,"MEDIA_LANGZEIT") -> 7 | E5: =COUNTIF(Sonderquests!$C$5:$C$18,"HIDDEN") -> 5 | F5: =COUNTIF(Sonderquests!$C$5:$C$18,"WORLD_BOSS") -> 2 | G5: =COUNTIF(Questgruppen!$F$5:$F$30,1) -> 6 | H5: =COUNTIFS(Questgruppen!$F$5:$F$30,">=2",Questgruppen!$F$5:$F$30,"<=5") -> 20 | I5: =ROUND(AVERAGE(Questgruppen!$AB$5:$AB$30),1) -> 4.3 | J5: =SUM(Questgruppen!$V$5:$V$30) -> 0 | K5: =COUNTA('Unique Gegner'!$B$5:$B$16) -> 12 | L5: =COUNTIF('Unique Gegner'!$D$5:$D$16,"DAY_1") -> 8 | M5: =COUNTIF('Unique Gegner'!$D$5:$D$16,"DAY_2") -> 4 | N5: =COUNTA('Quest Master'!A5:A44) -> 40 | O5: =COUNTA(Questablauf!A5:A400) -> 396 | P5: =COUNTA(Dialoge!A5:A124) -> 120 | Q5: =COUNTA(Charaktere!A5:A40) -> 36 | R5: =COUNTA(Rätsel!A5:A116) -> 112 | S5: =COUNTA(Kampfprofile!A5:A39) -> 35 | T5: =COUNTA(Navigation!A5:A8) -> 4 | U5: =COUNTA(Timer!A5:A10) -> 6 | V5: =COUNTIF(Abdeckung!U5:U16,"OK")+COUNTIF(Abdeckung!T19:T22,"OK") -> 16
A8: Hauptmechanik | B8: Reguläre Quests | C8: Empfohlener Korridor | D8: Bewertung | E8: Kommentar
A9: BEOBACHTUNG_SUCHE | B9: =COUNTIF(Questgruppen!$J$5:$J$30,A9) -> 4 | C9: 4–6 | D9: =IF(AND(B9>=4,B9<=6),"AUSGEWOGEN","PRUEFEN") -> AUSGEWOGEN | E9: GPS-Ort und lokale Beobachtung bleiben in jeder Quest Basiselemente.
A10: ZUORDNUNG_REIHENFOLGE | B10: =COUNTIF(Questgruppen!$J$5:$J$30,A10) -> 6 | C10: 4–6 | D10: =IF(AND(B10>=4,B10<=6),"AUSGEWOGEN","PRUEFEN") -> AUSGEWOGEN | E10: GPS-Ort und lokale Beobachtung bleiben in jeder Quest Basiselemente.
A11: KURZTEXT_RAETSEL | B11: =COUNTIF(Questgruppen!$J$5:$J$30,A11) -> 4 | C11: 4–6 | D11: =IF(AND(B11>=4,B11<=6),"AUSGEWOGEN","PRUEFEN") -> AUSGEWOGEN | E11: GPS-Ort und lokale Beobachtung bleiben in jeder Quest Basiselemente.
A12: DIALOG_ENTSCHEIDUNG | B12: =COUNTIF(Questgruppen!$J$5:$J$30,A12) -> 6 | C12: 4–6 | D12: =IF(AND(B12>=4,B12<=6),"AUSGEWOGEN","PRUEFEN") -> AUSGEWOGEN | E12: GPS-Ort und lokale Beobachtung bleiben in jeder Quest Basiselemente.
A13: KAMPF | B13: =COUNTIF(Questgruppen!$J$5:$J$30,A13) -> 6 | C13: 4–6 | D13: =IF(AND(B13>=4,B13<=6),"AUSGEWOGEN","PRUEFEN") -> AUSGEWOGEN | E13: GPS-Ort und lokale Beobachtung bleiben in jeder Quest Basiselemente.
A16: Wichtigste Entscheidung | B16: Begründung
A17: Die Kombinationen sind Quest-Card-reif, aber noch nicht eventfreigegeben. Aktueller Sichtbeleg, blinder Antworttest und Event-Recheck bleiben Pflicht.
A18: Nicht als Pflichtort verwendet: Obelisco della Minerva, Portico d’Ottavia, Piazza del Teatro di Pompeo, Meta Sudans und Arco di Via Nola.
A19: Operativ schwächste Kernkombinationen: Tore des Borgo, Das gebändigte Wasser, Stimmen der Republik und Tore der Aurelianischen Mauer. Sie benötigen die stärksten Fallbacks.

Sheet Matrixcheck
A1: Via Romae – Abgleich mit der Questmatrix
A2: Sollwerte aus den bisherigen Entscheidungen versus die konkrete Gruppierung.
A4: Dimension | B4: Ausprägung | C4: Soll | D4: Ist | E4: Check | F4: Bedeutung | G4: Abweichung | H4: Kommentar
A5: Reguläre Quests | B5: Tag 1 | C5: 16 | D5: =COUNTIF(Questgruppen!$C$5:$C$30,"DAY_1") -> 16 | E5: =IF(C5=D5,"OK","PRUEFEN") -> OK | F5: Tagesmenge | G5: =D5-C5 -> 0
A6: Reguläre Quests | B6: Tag 2 | C6: 10 | D6: =COUNTIF(Questgruppen!$C$5:$C$30,"DAY_2") -> 10 | E6: =IF(C6=D6,"OK","PRUEFEN") -> OK | F6: Tagesmenge | G6: =D6-C6 -> 0 | H6: 9–10 waren erlaubt; 10 nutzt die obere Zielgröße.
A7: Dauer | B7: 5–15 | C7: 8 | D7: =COUNTIF(Questgruppen!$G$5:$G$30,"5–15") -> 8 | E7: =IF(C7=D7,"OK","PRUEFEN") -> OK | F7: Kurze Quests | G7: =D7-C7 -> 0 | H7: Gleich viele wie 15–25.
A8: Dauer | B8: 15–25 | C8: 8 | D8: =COUNTIF(Questgruppen!$G$5:$G$30,"15–25") -> 8 | E8: =IF(C8=D8,"OK","PRUEFEN") -> OK | F8: Mittlere Quests | G8: =D8-C8 -> 0 | H8: Gleich viele wie 5–15.
A9: Dauer | B9: 25–35 | C9: 7 | D9: =COUNTIF(Questgruppen!$G$5:$G$30,"25–35") -> 7 | E9: =IF(C9=D9,"OK","PRUEFEN") -> OK | F9: Längere Quests | G9: =D9-C9 -> 0
A10: Dauer | B10: 35–45 | C10: 3 | D10: =COUNTIF(Questgruppen!$G$5:$G$30,"35–45") -> 3 | E10: =IF(C10=D10,"OK","PRUEFEN") -> OK | F10: Große Routen | G10: =D10-C10 -> 0
A11: Orte pro Quest | B11: 1 Ort | C11: 6 | D11: =COUNTIF(Questgruppen!$F$5:$F$30,1) -> 6 | E11: =IF(C11=D11,"OK","PRUEFEN") -> OK | F11: Reduzierter Ein-Ort-Anteil | G11: =D11-C11 -> 0 | H11: Nur rund ein Viertel der regulären Quests.
A12: Orte pro Quest | B12: 2–5 Orte | C12: 20 | D12: =COUNTIFS(Questgruppen!$F$5:$F$30,">=2",Questgruppen!$F$5:$F$30,"<=5") -> 20 | E12: =IF(C12=D12,"OK","PRUEFEN") -> OK | F12: Mehrortquests | G12: =D12-C12 -> 0
A13: Medien | B13: Tag 1 lokal | C13: 3 | D13: =COUNTIFS(Sonderquests!$C$5:$C$18,"MEDIA_LOCAL",Sonderquests!$D$5:$D$18,"DAY_1") -> 3 | E13: =IF(C13=D13,"OK","PRUEFEN") -> OK | F13: Separate Medienquests | G13: =D13-C13 -> 0
A14: Medien | B14: Tag 2 lokal | C14: 3 | D14: =COUNTIFS(Sonderquests!$C$5:$C$18,"MEDIA_LOCAL",Sonderquests!$D$5:$D$18,"DAY_2") -> 3 | E14: =IF(C14=D14,"OK","PRUEFEN") -> OK | F14: Separate Medienquests | G14: =D14-C14 -> 0
A15: Langzeit | B15: Bilderchronik | C15: 1 | D15: =COUNTIF(Sonderquests!$C$5:$C$18,"MEDIA_LANGZEIT") -> 1 | E15: =IF(C15=D15,"OK","PRUEFEN") -> OK | F15: Separater Chronikslot | G15: =D15-C15 -> 0
A16: Hidden | B16: Optionale Nebenquests | C16: 5 | D16: =COUNTIF(Sonderquests!$C$5:$C$18,"HIDDEN") -> 5 | E16: =IF(C16=D16,"OK","PRUEFEN") -> OK | F16: Zählen nicht zum Limit | G16: =D16-C16 -> 0 | H16: Zielkorridor war 4–6.
A17: Boss | B17: World Bosses | C17: 2 | D17: =COUNTIF(Sonderquests!$C$5:$C$18,"WORLD_BOSS") -> 2 | E17: =IF(C17=D17,"OK","PRUEFEN") -> OK | F17: Zählen nicht zum Limit | G17: =D17-C17 -> 0 | H17: Je ein Tagesfinale.
A18: Klassen | B18: Historienanker | C18: 4 | D18: =COUNTIF(Questgruppen!$M$5:$M$30,"SWISS_GUARD")+COUNTIF(Questgruppen!$M$5:$M$30,"CONDOTTIERE")+COUNTIF(Questgruppen!$M$5:$M$30,"SCULPTOR")+COUNTIF(Questgruppen!$M$5:$M$30,"CLERIC") -> 4 | E18: =IF(C18=D18,"OK","PRUEFEN") -> OK | F18: Je eine Quest pro Klasse | G18: =D18-C18 -> 0 | H18: Schweizergardist, Condottiere, Bildhauer, Kleriker.
A19: Sicherheit | B19: Rote Pflichtstationen | C19: 0 | D19: =SUM(Questgruppen!$V$5:$V$30) -> 0 | E19: =IF(C19=D19,"OK","PRUEFEN") -> OK | F19: Harter Ausschluss | G19: =D19-C19 -> 0
A20: Dauer | B20: Plausibilitätscheck OK | C20: 26 | D20: =COUNTIF(Questgruppen!$S$5:$S$30,"OK") -> 26 | E20: =IF(C20=D20,"OK","PRUEFEN") -> OK | F20: Gehzeit + Interaktion im Band | G20: =D20-C20 -> 0 | H20: Planungswert, kein Routing.
A21: Unique Gegner | B21: Tag 1 | C21: 8 | D21: =COUNTIF('Unique Gegner'!$D$5:$D$16,"DAY_1") -> 8 | E21: =IF(C21=D21,"OK","PRUEFEN") -> OK | F21: Eigenständige optionale Begegnungen | G21: =D21-C21 -> 0 | H21: Zählen weder zu regulären Quests noch Hidden Quests oder World Bosses.
A22: Unique Gegner | B22: Tag 2 | C22: 4 | D22: =COUNTIF('Unique Gegner'!$D$5:$D$16,"DAY_2") -> 4 | E22: =IF(C22=D22,"OK","PRUEFEN") -> OK | F22: Eigenständige optionale Begegnungen | G22: =D22-C22 -> 0 | H22: Rarität, Angriffsmuster und Stärke werden im Combat-Balancing festgelegt.

Sheet Questgruppen
A1: Via Romae – 26 reguläre Questgruppen
A2: 16 Quests an Tag 1, 10 an Tag 2. Sechs Ein-Ort-Quests; alle roten Kandidaten ausgeschlossen.
A4: Nr. | B4: Quest-ID | C4: Tag | D4: Arbeitstitel | E4: Orte in Reihenfolge | F4: Orte | G4: Dauerklasse | H4: Min | I4: Max | J4: Hauptmechanik | K4: Thema | L4: Epoche | M4: Klassenanker | N4: Gegner / Begegnung | O4: Gehstrecke (m) | P4: Gehminuten | Q4: Interaktionsminuten | R4: Gesamtminuten | S4: Dauercheck | T4: Grün | U4: Gelb | V4: Rot | W4: Route | X4: Narrativ | Y4: Hinweis | Z4: Zugang | AA4: Mechanikfit | AB4: Gesamtscore | AC4: Empfehlung | AD4: Hauptrisiko | AE4: Fallback
A5: 1 | B5: D1-Q01 | C5: DAY_1 | D5: Der Fluchtkorridor | E5: Petersplatz → Passetto di Borgo → Engelsburg | F5: =COUNTIF(Ortszuordnung!$A$5:$A$85,B5) -> 3 | G5: 25–35 | H5: 25 | I5: 35 | J5: DIALOG_ENTSCHEIDUNG | K5: Sacco di Roma, päpstlicher Schutz | L5: RENAISSANCE | M5: SWISS_GUARD | N5: Schatten des Passetto | O5: =SUMIF(Ortszuordnung!$A$5:$A$85,B5,Ortszuordnung!$S$5:$S$85) -> 1015 | P5: =ROUND(O5/Kriterien!$B$5,0) -> 14 | Q5: 18 | R5: =P5+Q5 -> 32 | S5: =IF(AND(R5>=H5,R5<=I5),"OK",IF(R5<H5,"ZU_KURZ","ZU_LANG")) -> OK | T5: =COUNTIFS(Ortszuordnung!$A$5:$A$85,B5,Ortszuordnung!$K$5:$K$85,"GRUEN") -> 2 | U5: =COUNTIFS(Ortszuordnung!$A$5:$A$85,B5,Ortszuordnung!$K$5:$K$85,"GELB") -> 1 | V5: =COUNTIFS(Ortszuordnung!$A$5:$A$85,B5,Ortszuordnung!$K$5:$K$85,"ROT") -> 0 | W5: 4.2 | X5: 5 | Y5: 3.8 | Z5: 3.4 | AA5: 4.8 | AB5: =ROUND(W5*Kriterien!$B$7+X5*Kriterien!$B$8+Y5*Kriterien!$B$9+Z5*Kriterien!$B$10+AA5*Kriterien!$B$11,1) -> 4.3 | AC5: =IF(V5>0,"NICHT_EMPFOHLEN",IF(AB5>=4.2,"SEHR_GUT",IF(AB5>=3.6,"GUT",IF(AB5>=3,"BEDINGT","NICHT_EMPFOHLEN")))) -> SEHR_GUT | AD5: Petersplatz: Menschenmenge und aktuelle Sicht der Bodenmarkierung. | AE5: Bei unklarer Bodenmarkierung startet die Quest am Passetto mit dessen Mauerverlauf.
A6: 2 | B6: D1-Q02 | C6: DAY_1 | D6: Tore des Borgo | E6: St.-Pellegrino-Tor → Porta Cavalleggeri → Porta Santo Spirito | F6: =COUNTIF(Ortszuordnung!$A$5:$A$85,B6) -> 3 | G6: 25–35 | H6: 25 | I6: 35 | J6: KAMPF | K6: Befestigung, päpstliche Macht | L6: RENAISSANCE | M6: CONDOTTIERE | N6: Cavalleggero Pontificio | O6: =SUMIF(Ortszuordnung!$A$5:$A$85,B6,Ortszuordnung!$S$5:$S$85) -> 970 | P6: =ROUND(O6/Kriterien!$B$5,0) -> 13 | Q6: 18 | R6: =P6+Q6 -> 31 | S6: =IF(AND(R6>=H6,R6<=I6),"OK",IF(R6<H6,"ZU_KURZ","ZU_LANG")) -> OK | T6: =COUNTIFS(Ortszuordnung!$A$5:$A$85,B6,Ortszuordnung!$K$5:$K$85,"GRUEN") -> 1 | U6: =COUNTIFS(Ortszuordnung!$A$5:$A$85,B6,Ortszuordnung!$K$5:$K$85,"GELB") -> 2 | V6: =COUNTIFS(Ortszuordnung!$A$5:$A$85,B6,Ortszuordnung!$K$5:$K$85,"ROT") -> 0 | W6: 3.8 | X6: 4.6 | Y6: 3.2 | Z6: 3.3 | AA6: 4.7 | AB6: =ROUND(W6*Kriterien!$B$7+X6*Kriterien!$B$8+Y6*Kriterien!$B$9+Z6*Kriterien!$B$10+AA6*Kriterien!$B$11,1) -> 3.9 | AC6: =IF(V6>0,"NICHT_EMPFOHLEN",IF(AB6>=4.2,"SEHR_GUT",IF(AB6>=3.6,"GUT",IF(AB6>=3,"BEDINGT","NICHT_EMPFOHLEN")))) -> GUT | AD6: Zwei Hinweise sind relativ klein; Cavalleggeri ist nur als Mauerrest erhalten. | AE6: Wenn Porta Cavalleggeri nicht eindeutig ist, endet die Quest an Porta Santo Spirito.
A7: 3 | B7: D1-Q03 | C7: DAY_1 | D7: Der Dreizack | E7: Piazza del Popolo → Obelisco Flaminio → Porta del Popolo | F7: =COUNTIF(Ortszuordnung!$A$5:$A$85,B7) -> 3 | G7: 15–25 | H7: 15 | I7: 25 | J7: BEOBACHTUNG_SUCHE | K7: Stadteingang und Stadtplanung | L7: ANTIKE_BIS_NEUZEIT | O7: =SUMIF(Ortszuordnung!$A$5:$A$85,B7,Ortszuordnung!$S$5:$S$85) -> 125 | P7: =ROUND(O7/Kriterien!$B$5,0) -> 2 | Q7: 15 | R7: =P7+Q7 -> 17 | S7: =IF(AND(R7>=H7,R7<=I7),"OK",IF(R7<H7,"ZU_KURZ","ZU_LANG")) -> OK | T7: =COUNTIFS(Ortszuordnung!$A$5:$A$85,B7,Ortszuordnung!$K$5:$K$85,"GRUEN") -> 3 | U7: =COUNTIFS(Ortszuordnung!$A$5:$A$85,B7,Ortszuordnung!$K$5:$K$85,"GELB") -> 0 | V7: =COUNTIFS(Ortszuordnung!$A$5:$A$85,B7,Ortszuordnung!$K$5:$K$85,"ROT") -> 0 | W7: 5 | X7: 4.5 | Y7: 4.8 | Z7: 4.2 | AA7: 4.8 | AB7: =ROUND(W7*Kriterien!$B$7+X7*Kriterien!$B$8+Y7*Kriterien!$B$9+Z7*Kriterien!$B$10+AA7*Kriterien!$B$11,1) -> 4.7 | AC7: =IF(V7>0,"NICHT_EMPFOHLEN",IF(AB7>=4.2,"SEHR_GUT",IF(AB7>=3.6,"GUT",IF(AB7>=3,"BEDINGT","NICHT_EMPFOHLEN")))) -> SEHR_GUT | AD7: Hohe Besucherzahl, aber alle Hinweise sind groß. | AE7: Bei dichter Menschenmenge nur Silhouetten und Großformen verwenden.
A8: 4 | B8: D1-Q04 | C8: DAY_1 | D8: Antinoos über Rom | E8: Obelisco di Antinoo → Fontana della Dea di Roma → Balconata del Pincio | F8: =COUNTIF(Ortszuordnung!$A$5:$A$85,B8) -> 3 | G8: 15–25 | H8: 15 | I8: 25 | J8: KAMPF | K8: Antinoos, Romulus und Remus, Pincio | L8: ANTIKE_REZEPTION | N8: Ombra di Antinoo | O8: =SUMIF(Ortszuordnung!$A$5:$A$85,B8,Ortszuordnung!$S$5:$S$85) -> 347 | P8: =ROUND(O8/Kriterien!$B$5,0) -> 5 | Q8: 15 | R8: =P8+Q8 -> 20 | S8: =IF(AND(R8>=H8,R8<=I8),"OK",IF(R8<H8,"ZU_KURZ","ZU_LANG")) -> OK | T8: =COUNTIFS(Ortszuordnung!$A$5:$A$85,B8,Ortszuordnung!$K$5:$K$85,"GRUEN") -> 3 | U8: =COUNTIFS(Ortszuordnung!$A$5:$A$85,B8,Ortszuordnung!$K$5:$K$85,"GELB") -> 0 | V8: =COUNTIFS(Ortszuordnung!$A$5:$A$85,B8,Ortszuordnung!$K$5:$K$85,"ROT") -> 0 | W8: 4.8 | X8: 4.5 | Y8: 4.5 | Z8: 4 | AA8: 4.7 | AB8: =ROUND(W8*Kriterien!$B$7+X8*Kriterien!$B$8+Y8*Kriterien!$B$9+Z8*Kriterien!$B$10+AA8*Kriterien!$B$11,1) -> 4.5 | AC8: =IF(V8>0,"NICHT_EMPFOHLEN",IF(AB8>=4.2,"SEHR_GUT",IF(AB8>=3.6,"GUT",IF(AB8>=3,"BEDINGT","NICHT_EMPFOHLEN")))) -> SEHR_GUT | AD8: Parkzugang und Tageszeit beachten. | AE8: Bei gesperrtem Pincio wird die Quest deaktiviert; kein entfernter Ersatzpunkt.
A9: 5 | B9: D1-Q05 | C9: DAY_1 | D9: Die steinerne Barke | E9: Spanischer Platz | F9: =COUNTIF(Ortszuordnung!$A$5:$A$85,B9) -> 1 | G9: 5–15 | H9: 5 | I9: 15 | J9: BEOBACHTUNG_SUCHE | K9: Barocke Stadtinszenierung | L9: BAROCK | O9: =SUMIF(Ortszuordnung!$A$5:$A$85,B9,Ortszuordnung!$S$5:$S$85) -> 0 | P9: =ROUND(O9/Kriterien!$B$5,0) -> 0 | Q9: 8 | R9: =P9+Q9 -> 8 | S9: =IF(AND(R9>=H9,R9<=I9),"OK",IF(R9<H9,"ZU_KURZ","ZU_LANG")) -> OK | T9: =COUNTIFS(Ortszuordnung!$A$5:$A$85,B9,Ortszuordnung!$K$5:$K$85,"GRUEN") -> 1 | U9: =COUNTIFS(Ortszuordnung!$A$5:$A$85,B9,Ortszuordnung!$K$5:$K$85,"GELB") -> 0 | V9: =COUNTIFS(Ortszuordnung!$A$5:$A$85,B9,Ortszuordnung!$K$5:$K$85,"ROT") -> 0 | W9: 5 | X9: 4 | Y9: 4.2 | Z9: 3 | AA9: 4.4 | AB9: =ROUND(W9*Kriterien!$B$7+X9*Kriterien!$B$8+Y9*Kriterien!$B$9+Z9*Kriterien!$B$10+AA9*Kriterien!$B$11,1) -> 4.2 | AC9: =IF(V9>0,"NICHT_EMPFOHLEN",IF(AB9>=4.2,"SEHR_GUT",IF(AB9>=3.6,"GUT",IF(AB9>=3,"BEDINGT","NICHT_EMPFOHLEN")))) -> SEHR_GUT | AD9: Extreme Menschenmenge; nur die große Bootsform ist robust. | AE9: Fallback ist die Richtung der großen Treppe zu Trinità dei Monti.
A10: 6 | B10: D1-Q06 | C10: DAY_1 | D10: Berninis Werkstatt | E10: Piazza Navona → Neptunsbrunnen → Mohrenbrunnen | F10: =COUNTIF(Ortszuordnung!$A$5:$A$85,B10) -> 3 | G10: 15–25 | H10: 15 | I10: 25 | J10: ZUORDNUNG_REIHENFOLGE | K10: Bildhauerei und barocke Platzdramaturgie | L10: BAROCK | M10: SCULPTOR | O10: =SUMIF(Ortszuordnung!$A$5:$A$85,B10,Ortszuordnung!$S$5:$S$85) -> 355 | P10: =ROUND(O10/Kriterien!$B$5,0) -> 5 | Q10: 18 | R10: =P10+Q10 -> 23 | S10: =IF(AND(R10>=H10,R10<=I10),"OK",IF(R10<H10,"ZU_KURZ","ZU_LANG")) -> OK | T10: =COUNTIFS(Ortszuordnung!$A$5:$A$85,B10,Ortszuordnung!$K$5:$K$85,"GRUEN") -> 3 | U10: =COUNTIFS(Ortszuordnung!$A$5:$A$85,B10,Ortszuordnung!$K$5:$K$85,"GELB") -> 0 | V10: =COUNTIFS(Ortszuordnung!$A$5:$A$85,B10,Ortszuordnung!$K$5:$K$85,"ROT") -> 0 | W10: 5 | X10: 5 | Y10: 4.5 | Z10: 3.4 | AA10: 5 | AB10: =ROUND(W10*Kriterien!$B$7+X10*Kriterien!$B$8+Y10*Kriterien!$B$9+Z10*Kriterien!$B$10+AA10*Kriterien!$B$11,1) -> 4.6 | AC10: =IF(V10>0,"NICHT_EMPFOHLEN",IF(AB10>=4.2,"SEHR_GUT",IF(AB10>=3.6,"GUT",IF(AB10>=3,"BEDINGT","NICHT_EMPFOHLEN")))) -> SEHR_GUT | AD10: Menschenmenge; nur große Figurenattribute verwenden. | AE10: Fallback: Zahl und Lage der drei Brunnen statt einzelner Figurendetails.
A11: 7 | B11: D1-Q07 | C11: DAY_1 | D11: Agrippas Zeichen | E11: Pantheon → Obelisco Macuteo | F11: =COUNTIF(Ortszuordnung!$A$5:$A$85,B11) -> 2 | G11: 5–15 | H11: 5 | I11: 15 | J11: KURZTEXT_RAETSEL | K11: Pantheon und ägyptische Wiederverwendung | L11: ANTIKE_UND_PAEPSTLICHES_ROM | N11: Mummia dell’Iseo | O11: =SUMIF(Ortszuordnung!$A$5:$A$85,B11,Ortszuordnung!$S$5:$S$85) -> 96 | P11: =ROUND(O11/Kriterien!$B$5,0) -> 1 | Q11: 10 | R11: =P11+Q11 -> 11 | S11: =IF(AND(R11>=H11,R11<=I11),"OK",IF(R11<H11,"ZU_KURZ","ZU_LANG")) -> OK | T11: =COUNTIFS(Ortszuordnung!$A$5:$A$85,B11,Ortszuordnung!$K$5:$K$85,"GRUEN") -> 2 | U11: =COUNTIFS(Ortszuordnung!$A$5:$A$85,B11,Ortszuordnung!$K$5:$K$85,"GELB") -> 0 | V11: =COUNTIFS(Ortszuordnung!$A$5:$A$85,B11,Ortszuordnung!$K$5:$K$85,"ROT") -> 0 | W11: 5 | X11: 4.7 | Y11: 4.3 | Z11: 3.7 | AA11: 4.5 | AB11: =ROUND(W11*Kriterien!$B$7+X11*Kriterien!$B$8+Y11*Kriterien!$B$9+Z11*Kriterien!$B$10+AA11*Kriterien!$B$11,1) -> 4.5 | AC11: =IF(V11>0,"NICHT_EMPFOHLEN",IF(AB11>=4.2,"SEHR_GUT",IF(AB11>=3.6,"GUT",IF(AB11>=3,"BEDINGT","NICHT_EMPFOHLEN")))) -> SEHR_GUT | AD11: Pantheon-Außenpunkt und Besucherdichte müssen aktuell bestätigt werden. | AE11: Fallback: Portikusform am Pantheon und Obelisk-auf-Brunnen-Beziehung.
A12: 8 | B12: D1-Q08 | C12: DAY_1 | D12: Kaiserbotschaften | E12: Obelisco di Montecitorio → Mark-Aurel-Säule | F12: =COUNTIF(Ortszuordnung!$A$5:$A$85,B12) -> 2 | G12: 5–15 | H12: 5 | I12: 15 | J12: ZUORDNUNG_REIHENFOLGE | K12: Imperiale Erinnerung im Stadtraum | L12: ANTIKE_UND_NEUZEIT | O12: =SUMIF(Ortszuordnung!$A$5:$A$85,B12,Ortszuordnung!$S$5:$S$85) -> 139 | P12: =ROUND(O12/Kriterien!$B$5,0) -> 2 | Q12: 10 | R12: =P12+Q12 -> 12 | S12: =IF(AND(R12>=H12,R12<=I12),"OK",IF(R12<H12,"ZU_KURZ","ZU_LANG")) -> OK | T12: =COUNTIFS(Ortszuordnung!$A$5:$A$85,B12,Ortszuordnung!$K$5:$K$85,"GRUEN") -> 2 | U12: =COUNTIFS(Ortszuordnung!$A$5:$A$85,B12,Ortszuordnung!$K$5:$K$85,"GELB") -> 0 | V12: =COUNTIFS(Ortszuordnung!$A$5:$A$85,B12,Ortszuordnung!$K$5:$K$85,"ROT") -> 0 | W12: 4.8 | X12: 4.6 | Y12: 4.8 | Z12: 4 | AA12: 4.5 | AB12: =ROUND(W12*Kriterien!$B$7+X12*Kriterien!$B$8+Y12*Kriterien!$B$9+Z12*Kriterien!$B$10+AA12*Kriterien!$B$11,1) -> 4.6 | AC12: =IF(V12>0,"NICHT_EMPFOHLEN",IF(AB12>=4.2,"SEHR_GUT",IF(AB12>=3.6,"GUT",IF(AB12>=3,"BEDINGT","NICHT_EMPFOHLEN")))) -> SEHR_GUT | AD12: Verkehr und Menschenmenge, Hinweise selbst sind groß. | AE12: Fallback: Form des Reliefbands beziehungsweise Schriftart am Obelisken.
A13: 9 | B13: D1-Q09 | C13: DAY_1 | D13: Das gebändigte Wasser | E13: Trevi-Brunnen → Acquedotto Vergine → Tritonenbrunnen | F13: =COUNTIF(Ortszuordnung!$A$5:$A$85,B13) -> 3 | G13: 25–35 | H13: 25 | I13: 35 | J13: KAMPF | K13: Wasserversorgung und Brunnenkunst | L13: ANTIKE_BIS_BAROCK | N13: Ratto dell’Acqua Virgo | O13: =SUMIF(Ortszuordnung!$A$5:$A$85,B13,Ortszuordnung!$S$5:$S$85) -> 747 | P13: =ROUND(O13/Kriterien!$B$5,0) -> 10 | Q13: 18 | R13: =P13+Q13 -> 28 | S13: =IF(AND(R13>=H13,R13<=I13),"OK",IF(R13<H13,"ZU_KURZ","ZU_LANG")) -> OK | T13: =COUNTIFS(Ortszuordnung!$A$5:$A$85,B13,Ortszuordnung!$K$5:$K$85,"GRUEN") -> 1 | U13: =COUNTIFS(Ortszuordnung!$A$5:$A$85,B13,Ortszuordnung!$K$5:$K$85,"GELB") -> 2 | V13: =COUNTIFS(Ortszuordnung!$A$5:$A$85,B13,Ortszuordnung!$K$5:$K$85,"ROT") -> 0 | W13: 3.7 | X13: 4.8 | Y13: 3.2 | Z13: 2.8 | AA13: 4.6 | AB13: =ROUND(W13*Kriterien!$B$7+X13*Kriterien!$B$8+Y13*Kriterien!$B$9+Z13*Kriterien!$B$10+AA13*Kriterien!$B$11,1) -> 3.9 | AC13: =IF(V13>0,"NICHT_EMPFOHLEN",IF(AB13>=4.2,"SEHR_GUT",IF(AB13>=3.6,"GUT",IF(AB13>=3,"BEDINGT","NICHT_EMPFOHLEN")))) -> GUT | AD13: Trevi ist extrem voll; die antiken Arkaden sind teilweise verdeckt. | AE13: Wenn die Arkaden verdeckt sind, nutzt die gleichörtige Materialfrage und setzt die Route fort.
A14: 10 | B14: D1-Q10 | C14: DAY_1 | D14: Macht auf dem Quirinal | E14: Piazza Scanderbeg → Obelisco del Quirinale → Quirinalspalast | F14: =COUNTIF(Ortszuordnung!$A$5:$A$85,B14) -> 3 | G14: 25–35 | H14: 25 | I14: 35 | J14: DIALOG_ENTSCHEIDUNG | K14: Söldner, Papst und Republik | L14: RENAISSANCE_BIS_GEGENWART | N14: Corazziere del Colle | O14: =SUMIF(Ortszuordnung!$A$5:$A$85,B14,Ortszuordnung!$S$5:$S$85) -> 534 | P14: =ROUND(O14/Kriterien!$B$5,0) -> 7 | Q14: 22 | R14: =P14+Q14 -> 29 | S14: =IF(AND(R14>=H14,R14<=I14),"OK",IF(R14<H14,"ZU_KURZ","ZU_LANG")) -> OK | T14: =COUNTIFS(Ortszuordnung!$A$5:$A$85,B14,Ortszuordnung!$K$5:$K$85,"GRUEN") -> 2 | U14: =COUNTIFS(Ortszuordnung!$A$5:$A$85,B14,Ortszuordnung!$K$5:$K$85,"GELB") -> 1 | V14: =COUNTIFS(Ortszuordnung!$A$5:$A$85,B14,Ortszuordnung!$K$5:$K$85,"ROT") -> 0 | W14: 4.5 | X14: 4.6 | Y14: 3.5 | Z14: 3.2 | AA14: 4.7 | AB14: =ROUND(W14*Kriterien!$B$7+X14*Kriterien!$B$8+Y14*Kriterien!$B$9+Z14*Kriterien!$B$10+AA14*Kriterien!$B$11,1) -> 4.1 | AC14: =IF(V14>0,"NICHT_EMPFOHLEN",IF(AB14>=4.2,"SEHR_GUT",IF(AB14>=3.6,"GUT",IF(AB14>=3,"BEDINGT","NICHT_EMPFOHLEN")))) -> GUT | AD14: Scanderbeg-Inschrift ist klein; am Palast Sicherheitsabstand einhalten. | AE14: Bei unleserlicher Scanderbeg-Inschrift beginnt die Quest am Quirinal-Obelisken.
A15: 11 | B15: D1-Q11 | C15: DAY_1 | D15: Zeichen der Unbefleckten | E15: Colonna dell'Immacolata | F15: =COUNTIF(Ortszuordnung!$A$5:$A$85,B15) -> 1 | G15: 5–15 | H15: 5 | I15: 15 | J15: KURZTEXT_RAETSEL | K15: Marienverehrung und Stadtsymbolik | L15: NEUZEIT | O15: =SUMIF(Ortszuordnung!$A$5:$A$85,B15,Ortszuordnung!$S$5:$S$85) -> 0 | P15: =ROUND(O15/Kriterien!$B$5,0) -> 0 | Q15: 9 | R15: =P15+Q15 -> 9 | S15: =IF(AND(R15>=H15,R15<=I15),"OK",IF(R15<H15,"ZU_KURZ","ZU_LANG")) -> OK | T15: =COUNTIFS(Ortszuordnung!$A$5:$A$85,B15,Ortszuordnung!$K$5:$K$85,"GRUEN") -> 1 | U15: =COUNTIFS(Ortszuordnung!$A$5:$A$85,B15,Ortszuordnung!$K$5:$K$85,"GELB") -> 0 | V15: =COUNTIFS(Ortszuordnung!$A$5:$A$85,B15,Ortszuordnung!$K$5:$K$85,"ROT") -> 0 | W15: 5 | X15: 4.2 | Y15: 4.7 | Z15: 3.8 | AA15: 4.2 | AB15: =ROUND(W15*Kriterien!$B$7+X15*Kriterien!$B$8+Y15*Kriterien!$B$9+Z15*Kriterien!$B$10+AA15*Kriterien!$B$11,1) -> 4.4 | AC15: =IF(V15>0,"NICHT_EMPFOHLEN",IF(AB15>=4.2,"SEHR_GUT",IF(AB15>=3.6,"GUT",IF(AB15>=3,"BEDINGT","NICHT_EMPFOHLEN")))) -> SEHR_GUT | AD15: Menschenmenge, aber klare Silhouette. | AE15: Fallback: Zahl der großen Sockelfiguren.
A16: 12 | B16: D1-Q12 | C16: DAY_1 | D16: Stimmen der Republik | E16: Ponte Sisto → Palazzo Farnese → Campo de' Fiori → Largo di Torre Argentina | F16: =COUNTIF(Ortszuordnung!$A$5:$A$85,B16) -> 4 | G16: 35–45 | H16: 35 | I16: 45 | J16: DIALOG_ENTSCHEIDUNG | K16: Macht, Markt und republikanische Erinnerung | L16: ANTIKE_BIS_NEUZEIT | O16: =SUMIF(Ortszuordnung!$A$5:$A$85,B16,Ortszuordnung!$S$5:$S$85) -> 1009 | P16: =ROUND(O16/Kriterien!$B$5,0) -> 13 | Q16: 24 | R16: =P16+Q16 -> 37 | S16: =IF(AND(R16>=H16,R16<=I16),"OK",IF(R16<H16,"ZU_KURZ","ZU_LANG")) -> OK | T16: =COUNTIFS(Ortszuordnung!$A$5:$A$85,B16,Ortszuordnung!$K$5:$K$85,"GRUEN") -> 2 | U16: =COUNTIFS(Ortszuordnung!$A$5:$A$85,B16,Ortszuordnung!$K$5:$K$85,"GELB") -> 2 | V16: =COUNTIFS(Ortszuordnung!$A$5:$A$85,B16,Ortszuordnung!$K$5:$K$85,"ROT") -> 0 | W16: 4.2 | X16: 5 | Y16: 3.6 | Z16: 3.3 | AA16: 4.8 | AB16: =ROUND(W16*Kriterien!$B$7+X16*Kriterien!$B$8+Y16*Kriterien!$B$9+Z16*Kriterien!$B$10+AA16*Kriterien!$B$11,1) -> 4.2 | AC16: =IF(V16>0,"NICHT_EMPFOHLEN",IF(AB16>=4.2,"SEHR_GUT",IF(AB16>=3.6,"GUT",IF(AB16>=3,"BEDINGT","NICHT_EMPFOHLEN")))) -> SEHR_GUT | AD16: Campo-Marktzeiten, Palazzo-Sicherheitsbereich und Überblick am Largo. | AE16: Jeder Abschnitt ist modular deaktivierbar; mindestens drei der vier Stationen müssen verfügbar sein.
A17: 13 | B17: D1-Q13 | C17: DAY_1 | D17: Roms große Bühne | E17: Basilica di Sant'Andrea della Valle → Fontana delle Tartarughe → Marcellustheater | F17: =COUNTIF(Ortszuordnung!$A$5:$A$85,B17) -> 3 | G17: 15–25 | H17: 15 | I17: 25 | J17: ZUORDNUNG_REIHENFOLGE | K17: Theater, Fassade und barocke Inszenierung | L17: ANTIKE_BIS_BAROCK | N17: Custode delle Tartarughe | O17: =SUMIF(Ortszuordnung!$A$5:$A$85,B17,Ortszuordnung!$S$5:$S$85) -> 784 | P17: =ROUND(O17/Kriterien!$B$5,0) -> 10 | Q17: 15 | R17: =P17+Q17 -> 25 | S17: =IF(AND(R17>=H17,R17<=I17),"OK",IF(R17<H17,"ZU_KURZ","ZU_LANG")) -> OK | T17: =COUNTIFS(Ortszuordnung!$A$5:$A$85,B17,Ortszuordnung!$K$5:$K$85,"GRUEN") -> 2 | U17: =COUNTIFS(Ortszuordnung!$A$5:$A$85,B17,Ortszuordnung!$K$5:$K$85,"GELB") -> 1 | V17: =COUNTIFS(Ortszuordnung!$A$5:$A$85,B17,Ortszuordnung!$K$5:$K$85,"ROT") -> 0 | W17: 4 | X17: 4.4 | Y17: 3.4 | Z17: 3.4 | AA17: 4.4 | AB17: =ROUND(W17*Kriterien!$B$7+X17*Kriterien!$B$8+Y17*Kriterien!$B$9+Z17*Kriterien!$B$10+AA17*Kriterien!$B$11,1) -> 3.9 | AC17: =IF(V17>0,"NICHT_EMPFOHLEN",IF(AB17>=4.2,"SEHR_GUT",IF(AB17>=3.6,"GUT",IF(AB17>=3,"BEDINGT","NICHT_EMPFOHLEN")))) -> GUT | AD17: Sant’Andrea-Fassadensicht und Schildkröten müssen aktuell bestätigt werden. | AE17: Fallback: Großformen an Sant’Andrea und Teatro; Tartarughen-Detail bei Bedarf auslassen.
A18: 14 | B18: D1-Q14 | C18: DAY_1 | D18: Die steinerne Insel | E18: Isola Tiberina | F18: =COUNTIF(Ortszuordnung!$A$5:$A$85,B18) -> 1 | G18: 5–15 | H18: 5 | I18: 15 | J18: KURZTEXT_RAETSEL | K18: Tiberinsel und Heiltradition | L18: ANTIKE_BIS_GEGENWART | O18: =SUMIF(Ortszuordnung!$A$5:$A$85,B18,Ortszuordnung!$S$5:$S$85) -> 0 | P18: =ROUND(O18/Kriterien!$B$5,0) -> 0 | Q18: 10 | R18: =P18+Q18 -> 10 | S18: =IF(AND(R18>=H18,R18<=I18),"OK",IF(R18<H18,"ZU_KURZ","ZU_LANG")) -> OK | T18: =COUNTIFS(Ortszuordnung!$A$5:$A$85,B18,Ortszuordnung!$K$5:$K$85,"GRUEN") -> 0 | U18: =COUNTIFS(Ortszuordnung!$A$5:$A$85,B18,Ortszuordnung!$K$5:$K$85,"GELB") -> 1 | V18: =COUNTIFS(Ortszuordnung!$A$5:$A$85,B18,Ortszuordnung!$K$5:$K$85,"ROT") -> 0 | W18: 5 | X18: 4.5 | Y18: 3.3 | Z18: 3.5 | AA18: 4.4 | AB18: =ROUND(W18*Kriterien!$B$7+X18*Kriterien!$B$8+Y18*Kriterien!$B$9+Z18*Kriterien!$B$10+AA18*Kriterien!$B$11,1) -> 4.1 | AC18: =IF(V18>0,"NICHT_EMPFOHLEN",IF(AB18>=4.2,"SEHR_GUT",IF(AB18>=3.6,"GUT",IF(AB18>=3,"BEDINGT","NICHT_EMPFOHLEN")))) -> GUT | AD18: Die Schiffsform ist nur vom richtigen Blickwinkel eindeutig. | AE18: Fallback: allgemeine Inselform und sichtbare Brückenbeziehung.
A19: 15 | B19: D1-Q15 | C19: DAY_1 | D19: Cecilias Stimmen | E19: Basilica di Santa Cecilia in Trastevere → Santa Maria in Trastevere | F19: =COUNTIF(Ortszuordnung!$A$5:$A$85,B19) -> 2 | G19: 15–25 | H19: 15 | I19: 25 | J19: DIALOG_ENTSCHEIDUNG | K19: Märtyrertradition, Musik und Titelkirchen | L19: FRUEHCHRISTLICH_BIS_MITTELALTER | M19: CLERIC | O19: =SUMIF(Ortszuordnung!$A$5:$A$85,B19,Ortszuordnung!$S$5:$S$85) -> 706 | P19: =ROUND(O19/Kriterien!$B$5,0) -> 9 | Q19: 16 | R19: =P19+Q19 -> 25 | S19: =IF(AND(R19>=H19,R19<=I19),"OK",IF(R19<H19,"ZU_KURZ","ZU_LANG")) -> OK | T19: =COUNTIFS(Ortszuordnung!$A$5:$A$85,B19,Ortszuordnung!$K$5:$K$85,"GRUEN") -> 1 | U19: =COUNTIFS(Ortszuordnung!$A$5:$A$85,B19,Ortszuordnung!$K$5:$K$85,"GELB") -> 1 | V19: =COUNTIFS(Ortszuordnung!$A$5:$A$85,B19,Ortszuordnung!$K$5:$K$85,"ROT") -> 0 | W19: 4.2 | X19: 5 | Y19: 3.3 | Z19: 3.2 | AA19: 4.8 | AB19: =ROUND(W19*Kriterien!$B$7+X19*Kriterien!$B$8+Y19*Kriterien!$B$9+Z19*Kriterien!$B$10+AA19*Kriterien!$B$11,1) -> 4.1 | AC19: =IF(V19>0,"NICHT_EMPFOHLEN",IF(AB19>=4.2,"SEHR_GUT",IF(AB19>=3.6,"GUT",IF(AB19>=3,"BEDINGT","NICHT_EMPFOHLEN")))) -> GUT | AD19: Santa Cecilia muss vollständig vom öffentlichen Außenpunkt funktionieren. | AE19: Wenn Santa Cecilia außen nicht eindeutig ist, startet die Quest auf der Piazza Santa Maria.
A20: 16 | B20: D1-Q16 | C20: DAY_1 | D20: Republik auf dem Gianicolo | E20: Gianicolense-Mauern → Mausoleo Ossario Garibaldino → Fontana Dell'Acqua Paola → Monumento a Garibaldi → Monumento ad Anita Garibaldi | F20: =COUNTIF(Ortszuordnung!$A$5:$A$85,B20) -> 5 | G20: 35–45 | H20: 35 | I20: 45 | J20: KAMPF | K20: Risorgimento und Verteidigung Roms | L20: 19_JAHRHUNDERT | N20: Garibaldino delle Mura | O20: =SUMIF(Ortszuordnung!$A$5:$A$85,B20,Ortszuordnung!$S$5:$S$85) -> 1404 | P20: =ROUND(O20/Kriterien!$B$5,0) -> 19 | Q20: 25 | R20: =P20+Q20 -> 44 | S20: =IF(AND(R20>=H20,R20<=I20),"OK",IF(R20<H20,"ZU_KURZ","ZU_LANG")) -> OK | T20: =COUNTIFS(Ortszuordnung!$A$5:$A$85,B20,Ortszuordnung!$K$5:$K$85,"GRUEN") -> 5 | U20: =COUNTIFS(Ortszuordnung!$A$5:$A$85,B20,Ortszuordnung!$K$5:$K$85,"GELB") -> 0 | V20: =COUNTIFS(Ortszuordnung!$A$5:$A$85,B20,Ortszuordnung!$K$5:$K$85,"ROT") -> 0 | W20: 3.5 | X20: 5 | Y20: 4.4 | Z20: 3.8 | AA20: 5 | AB20: =ROUND(W20*Kriterien!$B$7+X20*Kriterien!$B$8+Y20*Kriterien!$B$9+Z20*Kriterien!$B$10+AA20*Kriterien!$B$11,1) -> 4.4 | AC20: =IF(V20>0,"NICHT_EMPFOHLEN",IF(AB20>=4.2,"SEHR_GUT",IF(AB20>=3.6,"GUT",IF(AB20>=3,"BEDINGT","NICHT_EMPFOHLEN")))) -> SEHR_GUT | AD20: Steigung und längere Gehstrecke; kein Problem der Eintrittspflicht. | AE20: Die Quest kann auf vier Stationen gekürzt werden; Fontana Acqua Paola bleibt als Revive-Punkt erhalten.
A21: 17 | B21: D2-Q01 | C21: DAY_2 | D21: Stern des Kapitols | E21: Kapitolsplatz → Giulio Cesare | F21: =COUNTIF(Ortszuordnung!$A$5:$A$85,B21) -> 2 | G21: 15–25 | H21: 15 | I21: 25 | J21: ZUORDNUNG_REIHENFOLGE | K21: Kapitolinische Machtbilder | L21: ANTIKE_UND_RENAISSANCE | O21: =SUMIF(Ortszuordnung!$A$5:$A$85,B21,Ortszuordnung!$S$5:$S$85) -> 271 | P21: =ROUND(O21/Kriterien!$B$5,0) -> 4 | Q21: 15 | R21: =P21+Q21 -> 19 | S21: =IF(AND(R21>=H21,R21<=I21),"OK",IF(R21<H21,"ZU_KURZ","ZU_LANG")) -> OK | T21: =COUNTIFS(Ortszuordnung!$A$5:$A$85,B21,Ortszuordnung!$K$5:$K$85,"GRUEN") -> 1 | U21: =COUNTIFS(Ortszuordnung!$A$5:$A$85,B21,Ortszuordnung!$K$5:$K$85,"GELB") -> 1 | V21: =COUNTIFS(Ortszuordnung!$A$5:$A$85,B21,Ortszuordnung!$K$5:$K$85,"ROT") -> 0 | W21: 4.8 | X21: 4.8 | Y21: 4 | Z21: 4 | AA21: 4.7 | AB21: =ROUND(W21*Kriterien!$B$7+X21*Kriterien!$B$8+Y21*Kriterien!$B$9+Z21*Kriterien!$B$10+AA21*Kriterien!$B$11,1) -> 4.5 | AC21: =IF(V21>0,"NICHT_EMPFOHLEN",IF(AB21>=4.2,"SEHR_GUT",IF(AB21>=3.6,"GUT",IF(AB21>=3,"BEDINGT","NICHT_EMPFOHLEN")))) -> SEHR_GUT | AD21: Caesar-Attribut besitzt nur mittlere Quellen- und Sichtstärke. | AE21: Fallback: nur das robuste Stern-im-Oval-Muster des Platzes verwenden.
A22: 18 | B22: D2-Q02 | C22: DAY_2 | D22: Quadrigen der Einheit | E22: Nationaldenkmal für Viktor Emanuel II. | F22: =COUNTIF(Ortszuordnung!$A$5:$A$85,B22) -> 1 | G22: 5–15 | H22: 5 | I22: 15 | J22: BEOBACHTUNG_SUCHE | K22: Risorgimento und Nationalstaat | L22: 19_BIS_20_JAHRHUNDERT | O22: =SUMIF(Ortszuordnung!$A$5:$A$85,B22,Ortszuordnung!$S$5:$S$85) -> 0 | P22: =ROUND(O22/Kriterien!$B$5,0) -> 0 | Q22: 9 | R22: =P22+Q22 -> 9 | S22: =IF(AND(R22>=H22,R22<=I22),"OK",IF(R22<H22,"ZU_KURZ","ZU_LANG")) -> OK | T22: =COUNTIFS(Ortszuordnung!$A$5:$A$85,B22,Ortszuordnung!$K$5:$K$85,"GRUEN") -> 1 | U22: =COUNTIFS(Ortszuordnung!$A$5:$A$85,B22,Ortszuordnung!$K$5:$K$85,"GELB") -> 0 | V22: =COUNTIFS(Ortszuordnung!$A$5:$A$85,B22,Ortszuordnung!$K$5:$K$85,"ROT") -> 0 | W22: 5 | X22: 4.2 | Y22: 4.3 | Z22: 3.7 | AA22: 4.2 | AB22: =ROUND(W22*Kriterien!$B$7+X22*Kriterien!$B$8+Y22*Kriterien!$B$9+Z22*Kriterien!$B$10+AA22*Kriterien!$B$11,1) -> 4.3 | AC22: =IF(V22>0,"NICHT_EMPFOHLEN",IF(AB22>=4.2,"SEHR_GUT",IF(AB22>=3.6,"GUT",IF(AB22>=3,"BEDINGT","NICHT_EMPFOHLEN")))) -> SEHR_GUT | AD22: Menschenmenge; Quadrigen bleiben als Großform sichtbar. | AE22: Fallback: zentrale Reiterfigur statt Dachdetails.
A23: 19 | B23: D2-Q03 | C23: DAY_2 | D23: Arena und Triumph | E23: Konstantinsbogen → Kolosseum → Ludus Magnus | F23: =COUNTIF(Ortszuordnung!$A$5:$A$85,B23) -> 3 | G23: 25–35 | H23: 25 | I23: 35 | J23: KAMPF | K23: Triumph, Spektakel und Gladiatorentraining | L23: ANTIKE | N23: Gladiator des Ludus | O23: =SUMIF(Ortszuordnung!$A$5:$A$85,B23,Ortszuordnung!$S$5:$S$85) -> 446 | P23: =ROUND(O23/Kriterien!$B$5,0) -> 6 | Q23: 20 | R23: =P23+Q23 -> 26 | S23: =IF(AND(R23>=H23,R23<=I23),"OK",IF(R23<H23,"ZU_KURZ","ZU_LANG")) -> OK | T23: =COUNTIFS(Ortszuordnung!$A$5:$A$85,B23,Ortszuordnung!$K$5:$K$85,"GRUEN") -> 3 | U23: =COUNTIFS(Ortszuordnung!$A$5:$A$85,B23,Ortszuordnung!$K$5:$K$85,"GELB") -> 0 | V23: =COUNTIFS(Ortszuordnung!$A$5:$A$85,B23,Ortszuordnung!$K$5:$K$85,"ROT") -> 0 | W23: 5 | X23: 5 | Y23: 4.7 | Z23: 3.6 | AA23: 5 | AB23: =ROUND(W23*Kriterien!$B$7+X23*Kriterien!$B$8+Y23*Kriterien!$B$9+Z23*Kriterien!$B$10+AA23*Kriterien!$B$11,1) -> 4.7 | AC23: =IF(V23>0,"NICHT_EMPFOHLEN",IF(AB23>=4.2,"SEHR_GUT",IF(AB23>=3.6,"GUT",IF(AB23>=3,"BEDINGT","NICHT_EMPFOHLEN")))) -> SEHR_GUT | AD23: Sehr hohe Besucherzahl; nur Außenräume und Großformen. | AE23: Bei Überfüllung wird die Quest auf Konstantinsbogen und Ludus Magnus reduziert.
A24: 20 | B24: D2-Q04 | C24: DAY_2 | D24: Handel, Götter und Wahrheit | E24: Mund der Wahrheit → Tempel des Hercules Victor → Arco degli Argentari → Janusbogen | F24: =COUNTIF(Ortszuordnung!$A$5:$A$85,B24) -> 4 | G24: 35–45 | H24: 35 | I24: 45 | J24: DIALOG_ENTSCHEIDUNG | K24: Forum Boarium, Handel und Kulte | L24: ANTIKE_BIS_MITTELALTER | N24: Custode di Giano | O24: =SUMIF(Ortszuordnung!$A$5:$A$85,B24,Ortszuordnung!$S$5:$S$85) -> 390 | P24: =ROUND(O24/Kriterien!$B$5,0) -> 5 | Q24: 30 | R24: =P24+Q24 -> 35 | S24: =IF(AND(R24>=H24,R24<=I24),"OK",IF(R24<H24,"ZU_KURZ","ZU_LANG")) -> OK | T24: =COUNTIFS(Ortszuordnung!$A$5:$A$85,B24,Ortszuordnung!$K$5:$K$85,"GRUEN") -> 3 | U24: =COUNTIFS(Ortszuordnung!$A$5:$A$85,B24,Ortszuordnung!$K$5:$K$85,"GELB") -> 1 | V24: =COUNTIFS(Ortszuordnung!$A$5:$A$85,B24,Ortszuordnung!$K$5:$K$85,"ROT") -> 0 | W24: 5 | X24: 5 | Y24: 4.1 | Z24: 3.4 | AA24: 4.8 | AB24: =ROUND(W24*Kriterien!$B$7+X24*Kriterien!$B$8+Y24*Kriterien!$B$9+Z24*Kriterien!$B$10+AA24*Kriterien!$B$11,1) -> 4.5 | AC24: =IF(V24>0,"NICHT_EMPFOHLEN",IF(AB24>=4.2,"SEHR_GUT",IF(AB24>=3.6,"GUT",IF(AB24>=3,"BEDINGT","NICHT_EMPFOHLEN")))) -> SEHR_GUT | AD24: Bocca della Verità kann eine lange Warteschlange haben. | AE24: Bei Warteschlange wird die Bocca nur aus Distanz genutzt oder durch die Tempelform ersetzt.
A25: 21 | B25: D2-Q05 | C25: DAY_2 | D25: Masken über dem Circus | E25: Tritonenbrunnen → Belvedere Romolo E Remo → Maskenbrunnen bei Santa Sabina | F25: =COUNTIF(Ortszuordnung!$A$5:$A$85,B25) -> 3 | G25: 15–25 | H25: 15 | I25: 25 | J25: ZUORDNUNG_REIHENFOLGE | K25: Wasserfiguren und Aventinblick | L25: ANTIKE_REZEPTION_BIS_NEUZEIT | N25: Mascherone dell’Aventino | O25: =SUMIF(Ortszuordnung!$A$5:$A$85,B25,Ortszuordnung!$S$5:$S$85) -> 1079 | P25: =ROUND(O25/Kriterien!$B$5,0) -> 14 | Q25: 11 | R25: =P25+Q25 -> 25 | S25: =IF(AND(R25>=H25,R25<=I25),"OK",IF(R25<H25,"ZU_KURZ","ZU_LANG")) -> OK | T25: =COUNTIFS(Ortszuordnung!$A$5:$A$85,B25,Ortszuordnung!$K$5:$K$85,"GRUEN") -> 3 | U25: =COUNTIFS(Ortszuordnung!$A$5:$A$85,B25,Ortszuordnung!$K$5:$K$85,"GELB") -> 0 | V25: =COUNTIFS(Ortszuordnung!$A$5:$A$85,B25,Ortszuordnung!$K$5:$K$85,"ROT") -> 0 | W25: 4.2 | X25: 4.7 | Y25: 4.6 | Z25: 4 | AA25: 4.6 | AB25: =ROUND(W25*Kriterien!$B$7+X25*Kriterien!$B$8+Y25*Kriterien!$B$9+Z25*Kriterien!$B$10+AA25*Kriterien!$B$11,1) -> 4.5 | AC25: =IF(V25>0,"NICHT_EMPFOHLEN",IF(AB25>=4.2,"SEHR_GUT",IF(AB25>=3.6,"GUT",IF(AB25>=3,"BEDINGT","NICHT_EMPFOHLEN")))) -> SEHR_GUT | AD25: Kurzer Anstieg; Blickrichtung am Belvedere muss eindeutig sein. | AE25: Bei gesperrtem Brunnenbereich bleibt der Belvedere-Panoramafallback.
A26: 22 | B26: D2-Q06 | C26: DAY_2 | D26: Das steinerne Schiff | E26: Fontana della Navicella | F26: =COUNTIF(Ortszuordnung!$A$5:$A$85,B26) -> 1 | G26: 5–15 | H26: 5 | I26: 15 | J26: KURZTEXT_RAETSEL | K26: Antikenrezeption am Celio | L26: ANTIKE_REZEPTION | O26: =SUMIF(Ortszuordnung!$A$5:$A$85,B26,Ortszuordnung!$S$5:$S$85) -> 0 | P26: =ROUND(O26/Kriterien!$B$5,0) -> 0 | Q26: 9 | R26: =P26+Q26 -> 9 | S26: =IF(AND(R26>=H26,R26<=I26),"OK",IF(R26<H26,"ZU_KURZ","ZU_LANG")) -> OK | T26: =COUNTIFS(Ortszuordnung!$A$5:$A$85,B26,Ortszuordnung!$K$5:$K$85,"GRUEN") -> 1 | U26: =COUNTIFS(Ortszuordnung!$A$5:$A$85,B26,Ortszuordnung!$K$5:$K$85,"GELB") -> 0 | V26: =COUNTIFS(Ortszuordnung!$A$5:$A$85,B26,Ortszuordnung!$K$5:$K$85,"ROT") -> 0 | W26: 5 | X26: 4.2 | Y26: 4.4 | Z26: 4 | AA26: 4.1 | AB26: =ROUND(W26*Kriterien!$B$7+X26*Kriterien!$B$8+Y26*Kriterien!$B$9+Z26*Kriterien!$B$10+AA26*Kriterien!$B$11,1) -> 4.4 | AC26: =IF(V26>0,"NICHT_EMPFOHLEN",IF(AB26>=4.2,"SEHR_GUT",IF(AB26>=3.6,"GUT",IF(AB26>=3,"BEDINGT","NICHT_EMPFOHLEN")))) -> SEHR_GUT | AD26: Nur die Großform des Schiffs verwenden. | AE26: Fallback: Ausrichtung des Schiffs statt kleiner Details.
A27: 23 | B27: D2-Q07 | C27: DAY_2 | D27: Sitz der Kirche | E27: Lateranbasilika → Lateranischer Obelisk → Porta San Giovanni | F27: =COUNTIF(Ortszuordnung!$A$5:$A$85,B27) -> 3 | G27: 15–25 | H27: 15 | I27: 25 | J27: DIALOG_ENTSCHEIDUNG | K27: Lateran, Papsttum und Stadttor | L27: ANTIKE_BIS_BAROCK | O27: =SUMIF(Ortszuordnung!$A$5:$A$85,B27,Ortszuordnung!$S$5:$S$85) -> 657 | P27: =ROUND(O27/Kriterien!$B$5,0) -> 9 | Q27: 16 | R27: =P27+Q27 -> 25 | S27: =IF(AND(R27>=H27,R27<=I27),"OK",IF(R27<H27,"ZU_KURZ","ZU_LANG")) -> OK | T27: =COUNTIFS(Ortszuordnung!$A$5:$A$85,B27,Ortszuordnung!$K$5:$K$85,"GRUEN") -> 3 | U27: =COUNTIFS(Ortszuordnung!$A$5:$A$85,B27,Ortszuordnung!$K$5:$K$85,"GELB") -> 0 | V27: =COUNTIFS(Ortszuordnung!$A$5:$A$85,B27,Ortszuordnung!$K$5:$K$85,"ROT") -> 0 | W27: 4.7 | X27: 5 | Y27: 4.5 | Z27: 3.7 | AA27: 4.8 | AB27: =ROUND(W27*Kriterien!$B$7+X27*Kriterien!$B$8+Y27*Kriterien!$B$9+Z27*Kriterien!$B$10+AA27*Kriterien!$B$11,1) -> 4.6 | AC27: =IF(V27>0,"NICHT_EMPFOHLEN",IF(AB27>=4.2,"SEHR_GUT",IF(AB27>=3.6,"GUT",IF(AB27>=3,"BEDINGT","NICHT_EMPFOHLEN")))) -> SEHR_GUT | AD27: Menschenmenge und Verkehr, aber robuste Großformen. | AE27: Bei Verkehrssperre bleibt die Quest auf Basilika-Außenfassade und Obelisk.
A28: 24 | B28: D2-Q08 | C28: DAY_2 | D28: Tore der Aurelianischen Mauer | E28: Porta Latina → Porta Metronia | F28: =COUNTIF(Ortszuordnung!$A$5:$A$85,B28) -> 2 | G28: 25–35 | H28: 25 | I28: 35 | J28: ZUORDNUNG_REIHENFOLGE | K28: Stadtmauer und Verkehrsumbau | L28: ANTIKE_BIS_GEGENWART | N28: Scorpione delle Mura | O28: =SUMIF(Ortszuordnung!$A$5:$A$85,B28,Ortszuordnung!$S$5:$S$85) -> 899 | P28: =ROUND(O28/Kriterien!$B$5,0) -> 12 | Q28: 14 | R28: =P28+Q28 -> 26 | S28: =IF(AND(R28>=H28,R28<=I28),"OK",IF(R28<H28,"ZU_KURZ","ZU_LANG")) -> OK | T28: =COUNTIFS(Ortszuordnung!$A$5:$A$85,B28,Ortszuordnung!$K$5:$K$85,"GRUEN") -> 1 | U28: =COUNTIFS(Ortszuordnung!$A$5:$A$85,B28,Ortszuordnung!$K$5:$K$85,"GELB") -> 1 | V28: =COUNTIFS(Ortszuordnung!$A$5:$A$85,B28,Ortszuordnung!$K$5:$K$85,"ROT") -> 0 | W28: 3.2 | X28: 4.5 | Y28: 4.3 | Z28: 3.1 | AA28: 4.4 | AB28: =ROUND(W28*Kriterien!$B$7+X28*Kriterien!$B$8+Y28*Kriterien!$B$9+Z28*Kriterien!$B$10+AA28*Kriterien!$B$11,1) -> 4 | AC28: =IF(V28>0,"NICHT_EMPFOHLEN",IF(AB28>=4.2,"SEHR_GUT",IF(AB28>=3.6,"GUT",IF(AB28>=3,"BEDINGT","NICHT_EMPFOHLEN")))) -> GUT | AD28: Längere Gehstrecke und Verkehrsumfeld an Porta Metronia. | AE28: Wenn Porta Metronia nicht sicher anspielbar ist, wird nur Porta Latina als Kurzquest aktiviert.
A29: 25 | B29: D2-Q09 | C29: DAY_2 | D29: Schichten des Esquilino | E29: Basilika Groß Sankt Marien → Obelisco Esquilino → Thermae Traianae | F29: =COUNTIF(Ortszuordnung!$A$5:$A$85,B29) -> 3 | G29: 25–35 | H29: 25 | I29: 35 | J29: BEOBACHTUNG_SUCHE | K29: Kirche, Obelisk und antike Thermen | L29: ANTIKE_BIS_BAROCK | N29: Vapore delle Terme | O29: =SUMIF(Ortszuordnung!$A$5:$A$85,B29,Ortszuordnung!$S$5:$S$85) -> 1027 | P29: =ROUND(O29/Kriterien!$B$5,0) -> 14 | Q29: 20 | R29: =P29+Q29 -> 34 | S29: =IF(AND(R29>=H29,R29<=I29),"OK",IF(R29<H29,"ZU_KURZ","ZU_LANG")) -> OK | T29: =COUNTIFS(Ortszuordnung!$A$5:$A$85,B29,Ortszuordnung!$K$5:$K$85,"GRUEN") -> 2 | U29: =COUNTIFS(Ortszuordnung!$A$5:$A$85,B29,Ortszuordnung!$K$5:$K$85,"GELB") -> 1 | V29: =COUNTIFS(Ortszuordnung!$A$5:$A$85,B29,Ortszuordnung!$K$5:$K$85,"ROT") -> 0 | W29: 4 | X29: 5 | Y29: 4 | Z29: 3.2 | AA29: 4.6 | AB29: =ROUND(W29*Kriterien!$B$7+X29*Kriterien!$B$8+Y29*Kriterien!$B$9+Z29*Kriterien!$B$10+AA29*Kriterien!$B$11,1) -> 4.2 | AC29: =IF(V29>0,"NICHT_EMPFOHLEN",IF(AB29>=4.2,"SEHR_GUT",IF(AB29>=3.6,"GUT",IF(AB29>=3,"BEDINGT","NICHT_EMPFOHLEN")))) -> SEHR_GUT | AD29: Santa Maria Maggiore ist Bosszone und sehr belebt; Parkzugang zu den Thermen prüfen. | AE29: Bei Parkschließung endet die Quest am Esquilino-Obelisken.
A30: 26 | B30: D2-Q10 | C30: DAY_2 | D30: Wasser über dem Tor | E30: Porta Maggiore und Aqua Claudia | F30: =COUNTIF(Ortszuordnung!$A$5:$A$85,B30) -> 1 | G30: 5–15 | H30: 5 | I30: 15 | J30: KAMPF | K30: Aqua Claudia und Stadttor | L30: ANTIKE | N30: Idra dell’Aqua Claudia | O30: =SUMIF(Ortszuordnung!$A$5:$A$85,B30,Ortszuordnung!$S$5:$S$85) -> 0 | P30: =ROUND(O30/Kriterien!$B$5,0) -> 0 | Q30: 10 | R30: =P30+Q30 -> 10 | S30: =IF(AND(R30>=H30,R30<=I30),"OK",IF(R30<H30,"ZU_KURZ","ZU_LANG")) -> OK | T30: =COUNTIFS(Ortszuordnung!$A$5:$A$85,B30,Ortszuordnung!$K$5:$K$85,"GRUEN") -> 1 | U30: =COUNTIFS(Ortszuordnung!$A$5:$A$85,B30,Ortszuordnung!$K$5:$K$85,"GELB") -> 0 | V30: =COUNTIFS(Ortszuordnung!$A$5:$A$85,B30,Ortszuordnung!$K$5:$K$85,"ROT") -> 0 | W30: 5 | X30: 4.8 | Y30: 4.6 | Z30: 3.2 | AA30: 5 | AB30: =ROUND(W30*Kriterien!$B$7+X30*Kriterien!$B$8+Y30*Kriterien!$B$9+Z30*Kriterien!$B$10+AA30*Kriterien!$B$11,1) -> 4.6 | AC30: =IF(V30>0,"NICHT_EMPFOHLEN",IF(AB30>=4.2,"SEHR_GUT",IF(AB30>=3.6,"GUT",IF(AB30>=3,"BEDINGT","NICHT_EMPFOHLEN")))) -> SEHR_GUT | AD30: Sicherer Gehwegpunkt im Verkehrsknoten ist zwingend. | AE30: Bei ungeeignetem Gehwegpunkt wird die Quest vollständig deaktiviert.

Sheet Questdesign
A1: Via Romae – Questdesign-Entwürfe
A2: Narrativer Hook, Spielerhandlung, Belohnungsvariation, Hidden Opportunity und Fallback je regulärer Quest.
A4: Quest-ID | B4: Tag | C4: Arbeitstitel | D4: Narrativer Hook | E4: Kernhandlung der Spieler | F4: Sekundärmechaniken | G4: Belohnungsvariation | H4: Hidden Opportunity | I4: Fallback | J4: Redaktionsnotiz
A5: D1-Q01 | B5: DAY_1 | C5: Der Fluchtkorridor | D5: Rekonstruiert den Fluchtweg vom Petersplatz über den Passetto bis zur Engelsburg. | E5: An jedem Ort einen dauerhaften Hinweis identifizieren; am Ende entscheiden, wie die Nachhut den Rückzug deckt. | F5: GPS_ROUTE|BEOBACHTUNG|ZUORDNUNG|OPTIONALER_KAMPF | G5: Die Schlussentscheidung verändert Ruhm, Schutzbonus oder Kampfbelohnung. | H5: Ein unauffälliges Wappen kann einen kurzen Zusatzdialog der Schweizergarde öffnen. | I5: Bei unklarer Bodenmarkierung startet die Quest am Passetto mit dessen Mauerverlauf. | J5: Verbindlicher Klassenanker Schweizergardist; nur Außenpunkte.
A6: D1-Q02 | B6: DAY_1 | C6: Tore des Borgo | D6: Vergleicht drei sehr unterschiedliche Tore und entscheidet, welches ein Söldnerführer verteidigen würde. | E6: Torformen und Wappen zuordnen; taktische Entscheidung; Kampf gegen den päpstlichen Reiter. | F6: GPS_ROUTE|WAPPENSUCHE|FASSADENVERGLEICH|DIALOG | G6: Richtige Taktik gewährt Rüstungsbonus im Kampf. | H6: Das Borgia-Stiermotiv kann eine kurze Wappenspur auslösen. | I6: Wenn Porta Cavalleggeri nicht eindeutig ist, endet die Quest an Porta Santo Spirito. | J6: Verbindlicher Klassenanker Condottiere; aktuelle Sichtprüfung besonders wichtig.
A7: D1-Q03 | B7: DAY_1 | C7: Der Dreizack | D7: Lest Piazza, Obelisk und Tor als gemeinsam inszenierten nördlichen Eingang Roms. | E7: Dreizack erkennen, Löwen zählen und die Toröffnungen in die richtige historische Reihenfolge bringen. | F7: PANORAMABLICK|ZAEHLEN|REIHENFOLGE | G7: Fehlerfreie Reihenfolge gibt einen Navigationsbonus. | H7: Ein falscher Weg im Dreizack kann zu einer kurzen Irrläufer-Entscheidung führen. | I7: Bei dichter Menschenmenge nur Silhouetten und Großformen verwenden.
A8: D1-Q04 | B8: DAY_1 | C8: Antinoos über Rom | D8: Verbindet ägyptische Zeichen, Roms Gründungsbild und den Blick über die Stadt. | E8: Zeichen und Figuren zuordnen; die korrekte Deutung schwächt den Schatten des Antinoos. | F8: MYTHENFIGUREN|AUSSICHTSABGLEICH|ZUORDNUNG | G8: Jede richtige Zuordnung entfernt eine Gegnerfähigkeit. | H8: Die Wölfin kann eine optionale Gründungslegende öffnen. | I8: Bei gesperrtem Pincio wird die Quest deaktiviert; kein entfernter Ersatzpunkt.
A9: D1-Q05 | B9: DAY_1 | C9: Die steinerne Barke | D9: Erkennt, weshalb der Brunnen wie ein halb gesunkenes Boot wirkt. | E9: Ort erreichen, Großform bestimmen und zwischen vier Objektformen wählen. | F9: OBJEKTFORM|MULTIPLE_CHOICE | G9: Schneller Abschluss; kleiner Wissensbonus für die Bernini-Zuordnung. | H9: Keine Hidden-Komponente empfohlen: zu viele Passanten. | I9: Fallback ist die Richtung der großen Treppe zu Trinità dei Monti.
A10: D1-Q06 | B10: DAY_1 | C10: Berninis Werkstatt | D10: Lest die drei Brunnen als Werkstatt- und Inszenierungsraum des Barock. | E10: Brunnen ablaufen, Figurenattribute zuordnen und eine Werkstattentscheidung treffen. | F10: FIGURENDETAIL|VERGLEICH|DIALOG | G10: Die Werkstattwahl verändert Material- oder Ruhmbelohnung. | H10: Ein falsch zugeordnetes Tier kann einen humorvollen Lehrlingsauftrag öffnen. | I10: Fallback: Zahl und Lage der drei Brunnen statt einzelner Figurendetails. | J10: Verbindlicher Klassenanker Bildhauer; überschneidet sich bewusst mit Medienquest.
A11: D1-Q07 | B11: DAY_1 | C11: Agrippas Zeichen | D11: Entschlüsselt zwei kurze sichtbare Hinweise auf demselben Platz. | E11: AGRIPPA als normalisierte Texteingabe erfassen und den Obelisken seinem heutigen Träger zuordnen. | F11: INSCHRIFT|OBJEKTBEZIEHUNG|OPTIONALER_KAMPF | G11: Fehlerfreie Texteingabe schwächt die Mumie des Iseums. | H11: Die Hieroglyphen können einen optionalen Gegnerhinweis auslösen. | I11: Fallback: Portikusform am Pantheon und Obelisk-auf-Brunnen-Beziehung.
A12: D1-Q08 | B12: DAY_1 | C12: Kaiserbotschaften | D12: Vergleicht zwei Säulenmonumente und ihre sehr unterschiedlichen Bildsprachen. | E12: Hieroglyphen und Spiralrelief erkennen; Zweck und Bildsprache zuordnen. | F12: SCHRIFTERKENNUNG|RELIEFMUSTER|VERGLEICH | G12: Richtige Zuordnung gibt einen kurzen Wissensbonus. | H12: Keine zusätzliche Hidden Quest nötig. | I12: Fallback: Form des Reliefbands beziehungsweise Schriftart am Obelisken.
A13: D1-Q09 | B13: DAY_1 | C13: Das gebändigte Wasser | D13: Folgt der Aqua Virgo von sichtbaren Arkaden bis zu zwei monumentalen Brunnenbildern. | E13: Wasserweg nachvollziehen, große Figuren zählen und den Kanalratten-Gegner stellen. | F13: GPS_ROUTE|ARKADEN|FIGURENVERGLEICH | G13: Jeder korrekt gelesene Wasserhinweis reduziert eine Gift-/Schmutzfähigkeit. | H13: Die Arkaden können den versteckten Auftrag „Ratte des Aquädukts“ öffnen. | I13: Wenn die Arkaden verdeckt sind, nutzt die gleichörtige Materialfrage und setzt die Route fort.
A14: D1-Q10 | B14: DAY_1 | C14: Macht auf dem Quirinal | D14: Verfolgt, wie militärische und staatliche Macht am Quirinal sichtbar wird. | E14: Name, Pferdegruppe und heutige Institution erfassen; anschließend Loyalität wählen. | F14: INSCHRIFT|PFERDEGRUPPE|GESCHICHTSWAHL|OPTIONALER_KAMPF | G14: Die Loyalitätswahl verändert Dialog und Begegnungsbelohnung. | H14: Das Porträtrelief kann einen kurzen Söldnerkodex-Zweig öffnen. | I14: Bei unleserlicher Scanderbeg-Inschrift beginnt die Quest am Quirinal-Obelisken.
A15: D1-Q11 | B15: DAY_1 | C15: Zeichen der Unbefleckten | D15: Lest die Säule als Schichtung von antikem Material und neuzeitlicher Frömmigkeit. | E15: Spitzenfigur identifizieren und ihre Bedeutung in einer kurzen Auswahlfrage deuten. | F15: SILHOUETTE|SYMBOLDEUTUNG|MULTIPLE_CHOICE | G15: Kleine Wissens- oder Glaubensbelohnung. | H15: Keine Hidden-Komponente empfohlen. | I15: Fallback: Zahl der großen Sockelfiguren.
A16: D1-Q12 | B16: DAY_1 | C16: Stimmen der Republik | D16: Vergleicht, wie Brücke, Palast, Markt und Ruinen politische Macht erzählen. | E16: Vier große Hinweise sammeln und am Ende entscheiden, wessen Stimme im Stadtbild dominiert. | F16: GPS_ROUTE|WAPPEN|DENKMAL|GESCHICHTSWAHL | G16: Die Entscheidung verändert Ruhm, Wissen oder Denare. | H16: Giordano Brunos geschlossenes Buch kann einen Nebenauftrag auslösen. | I16: Jeder Abschnitt ist modular deaktivierbar; mindestens drei der vier Stationen müssen verfügbar sein.
A17: D1-Q13 | B17: DAY_1 | C17: Roms große Bühne | D17: Ordnet drei sehr verschiedene städtische Bühnen nach ihrer historischen Schicht. | E17: Fassadenasymmetrie, Brunnenfiguren und Arkadengeschosse erkennen und zeitlich ordnen. | F17: FASSADENDETAIL|FIGURENZAHL|SCHICHTENLESEN | G17: Richtige Reihenfolge gibt einen Dramaturgiebonus für die Bilderchronik. | H17: Die vier Schildkröten öffnen optional einen Wächterkampf. | I17: Fallback: Großformen an Sant’Andrea und Teatro; Tartarughen-Detail bei Bedarf auslassen.
A18: D1-Q14 | B18: DAY_1 | C18: Die steinerne Insel | D18: Verbindet die Schiffsform der Insel mit ihrer langen Geschichte als Heilort. | E18: Schiffsbug erkennen und die Tempelgeschichte in einem kurzen Rätsel deuten. | F18: FORMERKENNUNG|MEDIZINGESCHICHTE|DIALOG | G18: Richtige Deutung gewährt einen kleinen Heilbonus. | H18: Ein medizinisches Symbol kann einen Zusatzdialog öffnen. | I18: Fallback: allgemeine Inselform und sichtbare Brückenbeziehung.
A19: D1-Q15 | B19: DAY_1 | C19: Cecilias Stimmen | D19: Folgt der Erinnerung an Cecilia bis zum großen Mosaik von Santa Maria in Trastevere. | E19: Außenhinweise lesen und im Dialog entscheiden, wie Legende und belegte Geschichte getrennt erzählt werden. | F19: NAMENHINWEIS|FASSADENMOSAIK|SYMBOLDEUTUNG | G19: Sorgfältige Quellenwahl erhöht Glauben/Wissen statt bloßer Denare. | H19: Ein Musikbezug kann eine kurze klassenspezifische Nebenfrage öffnen. | I19: Wenn Santa Cecilia außen nicht eindeutig ist, startet die Quest auf der Piazza Santa Maria. | J19: Verbindlicher Klassenanker Kleriker; kein Innenraum.
A20: D1-Q16 | B20: DAY_1 | C20: Republik auf dem Gianicolo | D20: Steigt von den Mauern über das Ossarium und die Wasserfassade zu Garibaldi und Anita auf. | E20: Ereignisse und Denkmäler ordnen; am Ende Kampf gegen den Garibaldino der Mauern. | F20: GPS_ROUTE|DENKMAELER|WASSER|REIHENFOLGE | G20: Jede korrekt geordnete Station gibt dem Team einen gemeinsamen Buff. | H20: Ein Detail an Anitas Reitergruppe kann eine kurze Mutprobe öffnen. | I20: Die Quest kann auf vier Stationen gekürzt werden; Fontana Acqua Paola bleibt als Revive-Punkt erhalten.
A21: D2-Q01 | B21: DAY_2 | C21: Stern des Kapitols | D21: Lest Sternmuster und Caesarfigur als zwei bewusst gesetzte politische Zeichen. | E21: Muster und Attribut finden und den Aussagen Macht, Erinnerung oder Orientierung zuordnen. | F21: BODENMUSTER|FIGURENATTRIBUT|DIALOG | G21: Die Zuordnung verändert den folgenden Dialog. | H21: Keine Hidden-Komponente notwendig. | I21: Fallback: nur das robuste Stern-im-Oval-Muster des Platzes verwenden.
A22: D2-Q02 | B22: DAY_2 | C22: Quadrigen der Einheit | D22: Erkennt die zwei Quadrigen als monumentale Krönung des Nationaldenkmals. | E22: Großformen zählen und die Epoche des Denkmals zuordnen. | F22: SILHOUETTENZAEHLUNG|MULTIPLE_CHOICE | G22: Schneller Ruhmbonus. | H22: Keine Hidden-Komponente empfohlen. | I22: Fallback: zentrale Reiterfigur statt Dachdetails.
A23: D2-Q03 | B23: DAY_2 | C23: Arena und Triumph | D23: Verbindet Triumphbogen, Amphitheater und Trainingsarena zu einem Kampfkreislauf. | E23: Durchgänge und Arenaform lesen; daraus eine Taktik gegen den Gladiator ableiten. | F23: BOGENZAEHLUNG|ARENAFORM|TAKTIK | G23: Richtige Taktik beeinflusst Startinitiative und Beute. | H23: Ein Detail am Ludus kann einen optionalen Trainerdialog öffnen. | I23: Bei Überfüllung wird die Quest auf Konstantinsbogen und Ludus Magnus reduziert.
A24: D2-Q04 | B24: DAY_2 | C24: Handel, Götter und Wahrheit | D24: Lest vier eng benachbarte Monumente als Knoten von Handel, Kult und späterer Legende. | E24: Großformen vergleichen und am Ende entscheiden, welche Erklärung historisch, später oder legendär ist. | F24: GESICHTSDETAIL|BAUFORM|FORMVERGLEICH|RUNDGANG | G24: Saubere Trennung von Fakt und Legende erhöht Wissensbelohnung. | H24: Der Janusbogen kann einen optionalen Vier-Seiten-Wächter öffnen. | I24: Bei Warteschlange wird die Bocca nur aus Distanz genutzt oder durch die Tempelform ersetzt.
A25: D2-Q05 | B25: DAY_2 | C25: Masken über dem Circus | D25: Verbindet zwei Brunnenwesen mit dem Panorama über den Circus Maximus. | E25: Tritonen und Maske vergleichen und anschließend Palatin und Aventin richtig zuordnen. | F25: FIGURENVERGLEICH|MASKENDETAIL|PANORAMA | G25: Richtige Zuordnung gibt Bonus für die Streitwagen-Medienquest. | H25: Die Maske kann einen optionalen kurzen Gegnerkampf öffnen. | I25: Bei gesperrtem Brunnenbereich bleibt der Belvedere-Panoramafallback.
A26: D2-Q06 | B26: DAY_2 | C26: Das steinerne Schiff | D26: Deutet die Navicella als sichtbares Schiffssymbol vor dem Kirchenraum. | E26: Objektform erfassen und eine kurze Deutung auswählen oder eingeben. | F26: OBJEKTFORM|SYMBOLDEUTUNG | G26: Kleiner Navigations- oder Wissensbonus. | H26: Keine Hidden-Komponente empfohlen. | I26: Fallback: Ausrichtung des Schiffs statt kleiner Details.
A27: D2-Q07 | B27: DAY_2 | C27: Sitz der Kirche | D27: Verknüpft Kathedralfassade, Obelisk und Stadttor als geistliches und städtisches Machtzentrum. | E27: Drei Großhinweise erfassen und im Dialog geistliche, imperiale und städtische Funktion trennen. | F27: FASSADENSILHOUETTE|SCHRIFT|TORFORM | G27: Die Schlusswahl beeinflusst Glauben, Wissen oder Schutz. | H27: Eine klassenspezifische Klerikeroption ist sinnvoll, aber kein zusätzlicher Pflichtanker. | I27: Bei Verkehrssperre bleibt die Quest auf Basilika-Außenfassade und Obelisk.
A28: D2-Q08 | B28: DAY_2 | C28: Tore der Aurelianischen Mauer | D28: Vergleicht ein monumentales Tor mit einem vermauerten historischen Durchlass. | E28: Türme und Öffnungszustand erkennen; die beiden Orte nach Wehr- und Verkehrslogik zuordnen. | F28: GPS_ROUTE|ALT_NEU_VERGLEICH|TORFORM | G28: Richtige Zuordnung reduziert die Verteidigung des Mauerskorpions. | H28: Ein Mauerzeichen kann einen kurzen Nebenfund öffnen. | I28: Wenn Porta Metronia nicht sicher anspielbar ist, wird nur Porta Latina als Kurzquest aktiviert.
A29: D2-Q09 | B29: DAY_2 | C29: Schichten des Esquilino | D29: Lest drei sichtbare Schichten Roms vom Obelisken über die Basilika bis zur Ziegelruine. | E29: Großformen und Material erkennen; Schichten zeitlich ordnen; optionaler Dampfgegner. | F29: FASSADE|OBELISK|MATERIAL|OPTIONALER_KAMPF | G29: Richtige Chronologie gibt Widerstand gegen den späteren Boss. | H29: Der Thermendampf kann einen kurzen Kampf öffnen. | I29: Bei Parkschließung endet die Quest am Esquilino-Obelisken.
A30: D2-Q10 | B30: DAY_2 | C30: Wasser über dem Tor | D30: Erkennt den Doppelbogen als Tor und Träger zweier Wasserleitungen. | E30: Bögen und Aquäduktfunktion verbinden; danach kurzer Kampf gegen die Wasserhydra. | F30: DOPPELBOGEN|INFRASTRUKTUR|TAKTIK | G30: Korrekte Infrastrukturerklärung entfernt einen Hydrakopf. | H30: Keine zusätzliche Hidden Quest notwendig. | I30: Bei ungeeignetem Gehwegpunkt wird die Quest vollständig deaktiviert.

Sheet Mechanikbewertung
A1: Via Romae – Mechanikbewertung
A2: Eignung jeder Questkombination auf einer Skala von 0 bis 5. Null bedeutet irrelevant, fünf bedeutet ideal.
A4: Quest-ID | B4: Typ | C4: Tag | D4: Titel | E4: Orte | F4: Hauptmechanik | G4: GPS / Gehen | H4: Beobachtung / Suche | I4: Zählen / MC | J4: Zuordnen / Reihenfolge | K4: Kurze Texteingabe / Rätsel | L4: Dialog / Entscheidung | M4: Kampf | N4: Medien | O4: Max | P4: Stärkste Eignung | Q4: Warum funktioniert es? | R4: Schwäche / Bedingung
A5: D1-Q01 | B5: REGULAER | C5: DAY_1 | D5: Der Fluchtkorridor | E5: Petersplatz → Passetto di Borgo → Engelsburg | F5: DIALOG_ENTSCHEIDUNG | G5: 5 | H5: 4 | I5: 3 | J5: 3 | K5: 2 | L5: 5 | M5: 4 | N5: 0 | O5: =MAX(H5:N5) -> 5 | P5: =INDEX($H$4:$N$4,1,MATCH(O5,H5:N5,0)) -> Dialog / Entscheidung | Q5: An jedem Ort einen dauerhaften Hinweis identifizieren; am Ende entscheiden, wie die Nachhut den Rückzug deckt. | R5: Petersplatz: Menschenmenge und aktuelle Sicht der Bodenmarkierung.
A6: D1-Q02 | B6: REGULAER | C6: DAY_1 | D6: Tore des Borgo | E6: St.-Pellegrino-Tor → Porta Cavalleggeri → Porta Santo Spirito | F6: KAMPF | G6: 5 | H6: 4 | I6: 3 | J6: 3 | K6: 1 | L6: 4 | M6: 5 | N6: 0 | O6: =MAX(H6:N6) -> 5 | P6: =INDEX($H$4:$N$4,1,MATCH(O6,H6:N6,0)) -> Kampf | Q6: Torformen und Wappen zuordnen; taktische Entscheidung; Kampf gegen den päpstlichen Reiter. | R6: Zwei Hinweise sind relativ klein; Cavalleggeri ist nur als Mauerrest erhalten.
A7: D1-Q03 | B7: REGULAER | C7: DAY_1 | D7: Der Dreizack | E7: Piazza del Popolo → Obelisco Flaminio → Porta del Popolo | F7: BEOBACHTUNG_SUCHE | G7: 5 | H7: 5 | I7: 4 | J7: 2 | K7: 1 | L7: 2 | M7: 1 | N7: 0 | O7: =MAX(H7:N7) -> 5 | P7: =INDEX($H$4:$N$4,1,MATCH(O7,H7:N7,0)) -> Beobachtung / Suche | Q7: Dreizack erkennen, Löwen zählen und die Toröffnungen in die richtige historische Reihenfolge bringen. | R7: Hohe Besucherzahl, aber alle Hinweise sind groß.
A8: D1-Q04 | B8: REGULAER | C8: DAY_1 | D8: Antinoos über Rom | E8: Obelisco di Antinoo → Fontana della Dea di Roma → Balconata del Pincio | F8: KAMPF | G8: 5 | H8: 4 | I8: 3 | J8: 3 | K8: 1 | L8: 3 | M8: 5 | N8: 0 | O8: =MAX(H8:N8) -> 5 | P8: =INDEX($H$4:$N$4,1,MATCH(O8,H8:N8,0)) -> Kampf | Q8: Zeichen und Figuren zuordnen; die korrekte Deutung schwächt den Schatten des Antinoos. | R8: Parkzugang und Tageszeit beachten.
A9: D1-Q05 | B9: REGULAER | C9: DAY_1 | D9: Die steinerne Barke | E9: Spanischer Platz | F9: BEOBACHTUNG_SUCHE | G9: 3 | H9: 5 | I9: 4 | J9: 2 | K9: 1 | L9: 2 | M9: 1 | N9: 0 | O9: =MAX(H9:N9) -> 5 | P9: =INDEX($H$4:$N$4,1,MATCH(O9,H9:N9,0)) -> Beobachtung / Suche | Q9: Ort erreichen, Großform bestimmen und zwischen vier Objektformen wählen. | R9: Extreme Menschenmenge; nur die große Bootsform ist robust.
A10: D1-Q06 | B10: REGULAER | C10: DAY_1 | D10: Berninis Werkstatt | E10: Piazza Navona → Neptunsbrunnen → Mohrenbrunnen | F10: ZUORDNUNG_REIHENFOLGE | G10: 5 | H10: 4 | I10: 3 | J10: 5 | K10: 2 | L10: 4 | M10: 2 | N10: 0 | O10: =MAX(H10:N10) -> 5 | P10: =INDEX($H$4:$N$4,1,MATCH(O10,H10:N10,0)) -> Zuordnen / Reihenfolge | Q10: Brunnen ablaufen, Figurenattribute zuordnen und eine Werkstattentscheidung treffen. | R10: Menschenmenge; nur große Figurenattribute verwenden.
A11: D1-Q07 | B11: REGULAER | C11: DAY_1 | D11: Agrippas Zeichen | E11: Pantheon → Obelisco Macuteo | F11: KURZTEXT_RAETSEL | G11: 3 | H11: 4 | I11: 3 | J11: 3 | K11: 5 | L11: 3 | M11: 4 | N11: 0 | O11: =MAX(H11:N11) -> 5 | P11: =INDEX($H$4:$N$4,1,MATCH(O11,H11:N11,0)) -> Kurze Texteingabe / Rätsel | Q11: AGRIPPA als normalisierte Texteingabe erfassen und den Obelisken seinem heutigen Träger zuordnen. | R11: Pantheon-Außenpunkt und Besucherdichte müssen aktuell bestätigt werden.
A12: D1-Q08 | B12: REGULAER | C12: DAY_1 | D12: Kaiserbotschaften | E12: Obelisco di Montecitorio → Mark-Aurel-Säule | F12: ZUORDNUNG_REIHENFOLGE | G12: 4 | H12: 4 | I12: 3 | J12: 5 | K12: 2 | L12: 3 | M12: 2 | N12: 0 | O12: =MAX(H12:N12) -> 5 | P12: =INDEX($H$4:$N$4,1,MATCH(O12,H12:N12,0)) -> Zuordnen / Reihenfolge | Q12: Hieroglyphen und Spiralrelief erkennen; Zweck und Bildsprache zuordnen. | R12: Verkehr und Menschenmenge, Hinweise selbst sind groß.
A13: D1-Q09 | B13: REGULAER | C13: DAY_1 | D13: Das gebändigte Wasser | E13: Trevi-Brunnen → Acquedotto Vergine → Tritonenbrunnen | F13: KAMPF | G13: 5 | H13: 4 | I13: 3 | J13: 3 | K13: 1 | L13: 3 | M13: 5 | N13: 0 | O13: =MAX(H13:N13) -> 5 | P13: =INDEX($H$4:$N$4,1,MATCH(O13,H13:N13,0)) -> Kampf | Q13: Wasserweg nachvollziehen, große Figuren zählen und den Kanalratten-Gegner stellen. | R13: Trevi ist extrem voll; die antiken Arkaden sind teilweise verdeckt.
A14: D1-Q10 | B14: REGULAER | C14: DAY_1 | D14: Macht auf dem Quirinal | E14: Piazza Scanderbeg → Obelisco del Quirinale → Quirinalspalast | F14: DIALOG_ENTSCHEIDUNG | G14: 5 | H14: 4 | I14: 3 | J14: 3 | K14: 2 | L14: 5 | M14: 4 | N14: 0 | O14: =MAX(H14:N14) -> 5 | P14: =INDEX($H$4:$N$4,1,MATCH(O14,H14:N14,0)) -> Dialog / Entscheidung | Q14: Name, Pferdegruppe und heutige Institution erfassen; anschließend Loyalität wählen. | R14: Scanderbeg-Inschrift ist klein; am Palast Sicherheitsabstand einhalten.
A15: D1-Q11 | B15: REGULAER | C15: DAY_1 | D15: Zeichen der Unbefleckten | E15: Colonna dell'Immacolata | F15: KURZTEXT_RAETSEL | G15: 3 | H15: 4 | I15: 3 | J15: 3 | K15: 5 | L15: 3 | M15: 1 | N15: 0 | O15: =MAX(H15:N15) -> 5 | P15: =INDEX($H$4:$N$4,1,MATCH(O15,H15:N15,0)) -> Kurze Texteingabe / Rätsel | Q15: Spitzenfigur identifizieren und ihre Bedeutung in einer kurzen Auswahlfrage deuten. | R15: Menschenmenge, aber klare Silhouette.
